<?xml-model href="https://raw.githubusercontent.com/harleylara/urdfdom/refs/heads/movespecification/xsd/urdf.xsd"?>
<robot name="foxy_base" xmlns:xacro="http://www.ros.org/wiki/xacro">

  <!-- params description for xacro component -->
  <!-- root_frame: name of the root link frame -->
  <xacro:macro name="foxy_base" params="root_frame">

    <material name="grey">
      <color rgba="0.7 0.7 0.7 1" />
    </material>
    <material name="green">
      <color rgba="0 0.6 0 1" />
    </material>
    <material name="white">
      <color rgba="1 1 1 1" />
    </material>

    <link name="base_footprint" />

    <link name="${root_frame}">
      <visual>
        <geometry>
          <box size="0.6 0.4 0.2" />
        </geometry>
        <origin xyz="0 0 0.1" rpy="0 0 0" />
        <material name="green" />
      </visual>
    </link>

    <joint name="base_joint" type="fixed">
      <parent link="${root_frame}" />
      <child link="base_footprint" />
      <origin xyz="0 0 -0.1" rpy="0 0 0" />
    </joint>

    <link name="left_wheel">
      <visual>
        <geometry>
          <cylinder radius="0.1" length="0.05" />
        </geometry>
        <origin xyz="0 0 0" rpy="1.57 0 0" />
        <material name="grey" />
      </visual>
    </link>

    <link name="right_wheel">
      <visual>
        <geometry>
          <cylinder radius="0.1" length="0.05" />
        </geometry>
        <origin xyz="0 0 0" rpy="1.57 0 0" />
        <material name="grey" />
      </visual>
    </link>

    <link name="caster_wheel">
      <visual>
        <geometry>
          <sphere radius="0.05" />
        </geometry>
        <origin xyz="0 0 0" rpy="0 0 0" />
        <material name="grey" />
      </visual>
    </link>

    <joint name="base_left_wheel_joint" type="continuous">
      <parent link="${root_frame}" />
      <child link="left_wheel" />
      <origin xyz="-0.15 0.225 0" rpy="0 0 0" />
      <axis xyz="0 1 0"/>
    </joint>

    <joint name="base_right_wheel_joint" type="continuous">
      <parent link="${root_frame}" />
      <child link="right_wheel" />
      <origin xyz="-0.15 -0.225 0" rpy="0 0 0" />
      <axis xyz="0 1 0"/>
    </joint>

    <joint name="base_caster_wheel_joint" type="fixed">
      <parent link="${root_frame}" />
      <child link="caster_wheel" />
      <origin xyz="0.2 0 -0.05" rpy="0 0 0" />
    </joint>
  </xacro:macro>

</robot>
